<?xml version="1.0"?>
<!--
Simple 2-Joint Robot URDF
A minimal humanoid arm with shoulder and elbow joints for educational purposes.

Structure:
  base_link (fixed to world)
    └─ shoulder_link (revolute joint)
        └─ elbow_link (revolute joint)
            └─ end_effector_link (fixed)

Visualization: ros2 launch ros2_chapter1 simple_robot_launch.py
-->

<robot name="simple_2_joint_robot">

  <!-- Base Link (Fixed to World) -->
  <link name="base_link">
    <visual>
      <geometry>
        <box size="0.2 0.2 0.1"/>
      </geometry>
      <origin xyz="0 0 0.05" rpy="0 0 0"/>
      <material name="blue">
        <color rgba="0.2 0.2 0.8 1.0"/>
      </material>
    </visual>
    <collision>
      <geometry>
        <box size="0.2 0.2 0.1"/>
      </geometry>
      <origin xyz="0 0 0.05" rpy="0 0 0"/>
    </collision>
    <inertial>
      <mass value="1.0"/>
      <inertia ixx="0.01" ixy="0.0" ixz="0.0" iyy="0.01" iyz="0.0" izz="0.01"/>
    </inertial>
  </link>

  <!-- Shoulder Joint (Revolute - Pitch Motion) -->
  <joint name="shoulder_joint" type="revolute">
    <parent link="base_link"/>
    <child link="shoulder_link"/>
    <origin xyz="0 0 0.1" rpy="0 0 0"/>
    <axis xyz="0 1 0"/>  <!-- Rotates around Y-axis (pitch) -->
    <limit effort="10.0" lower="-1.57" upper="1.57" velocity="1.0"/>
    <dynamics damping="0.1" friction="0.05"/>
  </joint>

  <!-- Shoulder Link (Upper Arm) -->
  <link name="shoulder_link">
    <visual>
      <geometry>
        <cylinder radius="0.05" length="0.3"/>
      </geometry>
      <origin xyz="0 0 0.15" rpy="0 0 0"/>
      <material name="green">
        <color rgba="0.2 0.8 0.2 1.0"/>
      </material>
    </visual>
    <collision>
      <geometry>
        <cylinder radius="0.05" length="0.3"/>
      </geometry>
      <origin xyz="0 0 0.15" rpy="0 0 0"/>
    </collision>
    <inertial>
      <mass value="0.5"/>
      <origin xyz="0 0 0.15" rpy="0 0 0"/>
      <inertia ixx="0.005" ixy="0.0" ixz="0.0" iyy="0.005" iyz="0.0" izz="0.001"/>
    </inertial>
  </link>

  <!-- Elbow Joint (Revolute - Pitch Motion) -->
  <joint name="elbow_joint" type="revolute">
    <parent link="shoulder_link"/>
    <child link="elbow_link"/>
    <origin xyz="0 0 0.3" rpy="0 0 0"/>
    <axis xyz="0 1 0"/>  <!-- Rotates around Y-axis (pitch) -->
    <limit effort="5.0" lower="-2.0" upper="0.0" velocity="1.0"/>
    <dynamics damping="0.1" friction="0.05"/>
  </joint>

  <!-- Elbow Link (Forearm) -->
  <link name="elbow_link">
    <visual>
      <geometry>
        <cylinder radius="0.04" length="0.25"/>
      </geometry>
      <origin xyz="0 0 0.125" rpy="0 0 0"/>
      <material name="red">
        <color rgba="0.8 0.2 0.2 1.0"/>
      </material>
    </visual>
    <collision>
      <geometry>
        <cylinder radius="0.04" length="0.25"/>
      </geometry>
      <origin xyz="0 0 0.125" rpy="0 0 0"/>
    </collision>
    <inertial>
      <mass value="0.3"/>
      <origin xyz="0 0 0.125" rpy="0 0 0"/>
      <inertia ixx="0.002" ixy="0.0" ixz="0.0" iyy="0.002" iyz="0.0" izz="0.0005"/>
    </inertial>
  </link>

  <!-- End Effector (Hand/Gripper) - Fixed Joint -->
  <joint name="end_effector_joint" type="fixed">
    <parent link="elbow_link"/>
    <child link="end_effector_link"/>
    <origin xyz="0 0 0.25" rpy="0 0 0"/>
  </joint>

  <!-- End Effector Link -->
  <link name="end_effector_link">
    <visual>
      <geometry>
        <sphere radius="0.05"/>
      </geometry>
      <origin xyz="0 0 0" rpy="0 0 0"/>
      <material name="yellow">
        <color rgba="0.9 0.9 0.2 1.0"/>
      </material>
    </visual>
    <collision>
      <geometry>
        <sphere radius="0.05"/>
      </geometry>
      <origin xyz="0 0 0" rpy="0 0 0"/>
    </collision>
    <inertial>
      <mass value="0.1"/>
      <inertia ixx="0.0001" ixy="0.0" ixz="0.0" iyy="0.0001" iyz="0.0" izz="0.0001"/>
    </inertial>
  </link>

</robot>
